Workbook

Sheet 2026
A1: =NOW() -> 46234.098 | I1: {=(INDIRECT("I" & ROW() + 1)/INDIRECT("E" & ROW() + 1))} -> 0.71075895 | L1: {=(1 - INDIRECT("I" & ROW()))} -> 0.28924105
E2: =O22 -> 989130 | I2: =O7 -> 703033 | L2: =E2-I2 -> 286097
A3: Last updated | D3: Available to budget | I3: Spent this month | L3: Budgeted this month
C5: January
D6: CATEGORY | E6: WEEK1 (1-6) | G6: WEEK2(7-13) | I6: WEEK3 (14-20) | K6: WEEK4 (21-27) | M6: WEEK5 (23-31) | O6: TOTAL
D7: 🛍️ Expenses | E7: =SUM(E8:F21) -> 95653 | G7: =SUM(G8:H21) -> 344551 | I7: =SUM(I8:J21) -> 32856 | K7: =SUM(K8:L21) -> 218120 | M7: =SUM(M8:M21) -> 11853 | O7: =SUM(E7:N7) -> 703033
D8: Rent & bills | E8: 0 | G8: =282631 - 81315 -> 201316 | I8: 0 | K8: 0 | M8: 0 | O8: =SUM(E8:N8) -> 201316
D9: Groceries | E9: =941+2400+448+636+1986+520+589+1369 -> 8889 | G9: =1992+1390+1993+951+2988+4926+875 -> 15115 | I9: =1190+1845+298+1000+702+329+732+3168+650+329 -> 10243 | K9: =3978+1353+650+329+1201+999+3045+514 -> 12069 | M9: =908+1023+4044+1438+3190 -> 10603 | O9: =SUM(E9:N9) -> 56919
D10: Supplies & home | E10: =658+1250 -> 1908 | G10: =3740+2990+404+2120+239 -> 9493 | I10: 0 | K10: 0 | M10: 0 | O10: =SUM(E10:N10) -> 11401
D11: Dining Out | E11: =4444+3080+604 -> 8128 | G11: =3000+4330 -> 7330 | I11: =3050+4680+4980 -> 12710 | K11: =4973 -> 4973 | M11: 0 | O11: =SUM(E11:N11) -> 33141
D12: Drinking Out | E12: =1250+1250 -> 2500 | G12: =1490+1400+990 -> 3880 | I12: =2280/2+1313+1090 -> 3543 | K12: =2768+2340/2+1300 -> 5238 | M12: =1250 -> 1250 | O12: =SUM(E12:N12) -> 16411
D13: Electronics & digital | E13: 0 | G13: 0 | I13: 0 | K13: 0 | M13: 0 | O13: =SUM(E13:N13) -> 0
D14: Health & medicine | E14: 0 | G14: =6000 -> 6000 | I14: 420 | K14: =6000 -> 6000 | M14: 0 | O14: =SUM(E14:N14) -> 12420
D15: Fashion | E15: 0 | G15: =9890 -> 9890 | I15: 0 | K15: 0 | M15: 0 | O15: =SUM(E15:N15) -> 9890
D16: Vacation | E16: =49764 -> 49764 | G16: =30470 -> 30470 | I16: 0 | K16: 0 | M16: 0 | O16: =SUM(E16:N16) -> 80234
D17: Transport | E17: =8950+3880 -> 12830 | G17: 0 | I17: 0 | K17: 0 | M17: 0 | O17: =SUM(E17:N17) -> 12830
D18: Subscriptions | E18: 2245 | G18: 0 | I18: =4800 -> 4800 | K18: =765+9213+3728 -> 13706 | M18: 0 | O18: =SUM(E18:N18) -> 20751
D19: Gifts & dates | E19: =3750 -> 3750 | G19: 61057 | I19: =2280/2 -> 1140 | K19: =150775+18084 -> 168859 | M19: 0 | O19: =SUM(E19:N19) -> 234806
D20: Entertainment | E20: 0 | G20: 0 | I20: 0 | K20: =3875+600+2800 -> 7275 | M20: 0 | O20: =SUM(E20:N20) -> 7275
D21: Others | E21: =5639 -> 5639 | G21: 0 | I21: 0 | K21: 0 | M21: 0 | O21: =SUM(E21:N21) -> 5639
D22: 💰 Incomes | E22: =SUM(E23:F26) -> 945335 | G22: =SUM(G23:G26) -> 43795 | I22: =SUM(I23:I26) -> 0 | K22: =SUM(K23:K26) -> 0 | M22: =SUM(M23:M26) -> 0 | O22: =SUM(E22:N22) -> 989130
D23: Salary | E23: 945335 | G23: 0 | I23: 0 | K23: 0 | M23: 0 | O23: =SUM(E23:N23) -> 945335
D24: Cafeteria | E24: 0 | G24: 0 | I24: 0 | K24: 0 | M24: 0 | O24: =SUM(E24:N24) -> 0
D25: Gifts | E25: 0 | G25: 0 | I25: 0 | K25: 0 | M25: 0 | O25: =SUM(E25:N25) -> 0
D26: Others | E26: 0 | G26: =43795 -> 43795 | I26: 0 | K26: 0 | M26: 0 | O26: =SUM(E26:N26) -> 43795
A29: =NOW() -> 46234.098 | I29: {=(INDIRECT("I" & ROW() + 1)/INDIRECT("E" & ROW() + 1))} -> 0.59820236 | L29: {=(1 - INDIRECT("I" & ROW()))} -> 0.40179764
E30: =O50 -> 1286130 | I30: =O35 -> 769366 | L30: =E30-I30 -> 516764
A31: Last updated | D31: Available to budget | I31: Spent this month | L31: Budgeted this month
C33: February
D34: CATEGORY | E34: WEEK1 (1-6) | G34: WEEK2(7-13) | I34: WEEK3 (14-20) | K34: WEEK4 (21-27) | M34: WEEK5 (23-31) | O34: TOTAL
D35: 🛍️ Expenses | E35: =SUM(E36:F49) -> 203708 | G35: =SUM(G36:H49) -> 343883 | I35: =SUM(I36:J49) -> 94896 | K35: =SUM(K36:L49) -> 126480 | M35: =SUM(M36:M49) -> 399 | O35: =SUM(E35:N35) -> 769366
D36: Rent & bills | E36: 0 | G36: 209456 | I36: 0 | K36: 0 | M36: 0 | O36: =SUM(E36:N36) -> 209456
D37: Groceries | E37: =2614+469+650+2630+4686+1841+4038+650+329 -> 17907 | G37: =649+1092+4218+3497+3710+385+650 -> 14201 | I37: =2679+2556+4336+385+3705+185+1367 -> 15213 | K37: =2524+1030+2247+3976+2052+3012 -> 14841 | M37: 399 | O37: =SUM(E37:N37) -> 62561
D38: Supplies & home | E38: =1478+1500 -> 2978 | G38: =1098+1098+4290 -> 6486 | I38: =1245+6550+1320 -> 9115 | K38: =1399+1199+1759 -> 4357 | M38: 0 | O38: =SUM(E38:N38) -> 22936
D39: Dining Out | E39: =3532+3500+3500 -> 10532 | G39: =890+3500+891 -> 5281 | I39: =4140+2600 -> 6740 | K39: =3573+3150 -> 6723 | M39: 0 | O39: =SUM(E39:N39) -> 29276
D40: Drinking Out | E40: =2468+1250+1250 -> 4968 | G40: =1313+1300+1530+1250+1490+450 -> 7333 | I40: =1300+1250+1090+2500/2 -> 4890 | K40: =1300+1250+1490+2880/2 -> 5480 | M40: 0 | O40: =SUM(E40:N40) -> 22671
D41: Electronics & digital | E41: 60000 | G41: =7535 -> 7535 | I41: 0 | K41: 0 | M41: 0 | O41: =SUM(E41:N41) -> 67535
D42: Health & medicine | E42: =6000 -> 6000 | G42: 0 | I42: =6000 -> 6000 | K42: 0 | M42: 0 | O42: =SUM(E42:N42) -> 12000
D43: Fashion | E43: 0 | G43: =5995 -> 5995 | I43: 0 | K43: 0 | M43: 0 | O43: =SUM(E43:N43) -> 5995
D44: Vacation | E44: =11320+17760 -> 29080 | G44: 0 | I44: =1500+2454+21550+15345 -> 40849 | K44: 0 | M44: 0 | O44: =SUM(E44:N44) -> 69929
...

Sheet 2025
H1: {=(INDIRECT("G" & ROW() + 1)/INDIRECT("C" & ROW() + 1))} -> #DIV/0! | L1: {=(1 - INDIRECT("I" & ROW()))} -> 1
D2: =O22 -> 1015325 | H2: =O7 -> 632019 | K2: =D2-H2 -> 383306
C3: Available to budget | H3: Spent this month | K3: Budgeted this month
C5: January
D6: CATEGORY | E6: WEEK1 | G6: WEEK2 | I6: WEEK3 | K6: WEEK4 | M6: WEEK5 | O6: TOTAL
D7: 🛍️ Expenses | E7: =SUM(E8:F21) -> 54600 | G7: =SUM(G8:H21) -> 272095 | I7: =SUM(I8:J21) -> 158103 | K7: =SUM(K8:L21) -> 105832 | M7: =SUM(M8:M21) -> 41389 | O7: =SUM(E7:N7) -> 632019
D8: Rent & bills | E8: 0 | G8: =(279660-83600) -> 196060 | I8: 3770 | K8: 0 | M8: 0 | O8: =SUM(E8:N8) -> 199830
D9: Groceries | E9: =3227+5607+1898+900+4555 -> 16187 | G9: =499+549+300+4343+600+398+2084+843+1677 -> 11293 | I9: =2647+1693+6771+759+600+1497+2631+4292+4570 -> 25460 | K9: =310+2062+600+3150+389+2640+4523+3726 -> 17400 | M9: =3144+2917+2466+340+1219 -> 10086 | O9: =SUM(E9:N9) -> 80426
D10: Supplies & home | E10: =3547+870+1998 -> 6415 | G10: =810+1600 -> 2410 | I10: 0 | K10: =1219+2573+1599 -> 5391 | M10: 0 | O10: =SUM(E10:N10) -> 14216
D11: Dining Out | E11: =(16150/2) -> 8075 | G11: =(4360/2)+700 -> 2880 | I11: =4180+5601/2+10880 -> 17860.5 | K11: =700 -> 700 | M11: 0 | O11: =SUM(E11:N11) -> 29515.5
D12: Drinking Out | E12: =1109+1070+1150 -> 3329 | G12: =2300/2+900+955 -> 3005 | I12: =800+400+900+790 -> 2890 | K12: =1150+1150+1000+990 -> 4290 | M12: 1270 | O12: =SUM(E12:N12) -> 14784
D13: Electronics & digital | E13: 0 | G13: 0 | I13: 0 | K13: 0 | M13: 0 | O13: =SUM(E13:N13) -> 0
D14: Health & medicine | E14: 0 | G14: 0 | I14: 0 | K14: 33528 | M14: 360 | O14: =SUM(E14:N14) -> 33888
D15: Fashion | E15: 6995 | G15: =2295+8980 -> 11275 | I15: 1295 | K15: 0 | M15: 0 | O15: =SUM(E15:N15) -> 19565
D16: Vacation | E16: 0 | G16: 37314 | I16: 0 | K16: 0 | M16: 26403 | O16: =SUM(E16:N16) -> 63717
D17: Transport | E17: 0 | G17: 0 | I17: 8950 | K17: 0 | M17: 0 | O17: =SUM(E17:N17) -> 8950
D18: Subscriptions | E18: 2245 | G18: 0 | I18: 3596 | K18: 0 | M18: 0 | O18: =SUM(E18:N18) -> 5841
D19: Gifts & dates | E19: =1109+1070+(16150/2) -> 10254 | G19: =(4360/2)+2300/2+900+955 -> 5185 | I19: =15000+40096+33385+800+5601/2+900 -> 92981.5 | K19: =41633+1000+990 -> 43623 | M19: 1270 | O19: =SUM(E19:N19) -> 153313.5
D20: Entertainment | E20: 0 | G20: 0 | I20: 0 | K20: 0 | M20: 0 | O20: =SUM(E20:N20) -> 0
D21: Others | E21: 1100 | G21: =1573+1100 -> 2673 | I21: =1100+200 -> 1300 | K21: 900 | M21: 2000 | O21: =SUM(E21:N21) -> 7973
D22: 💰 Incomes | E22: =SUM(E23:F26) -> 46990 | G22: =SUM(G23:G26) -> 944335 | I22: =SUM(I23:I26) -> 9000 | K22: =SUM(K23:K26) -> 15000 | M22: =SUM(M23:M26) -> 0 | O22: =SUM(E22:N22) -> 1015325
D23: Salary | E23: 0 | G23: 944335 | J23: 0 | K23: 0 | M23: 0 | O23: =SUM(E23:N23) -> 944335
D24: Cafeteria | E24: 0 | H24: 0 | J24: 0 | L24: 0 | M24: 0 | O24: =SUM(E24:N24) -> 0
D25: Gifts | E25: 0 | G25: 0 | I25: 0 | K25: 0 | M25: 0 | O25: =SUM(E25:N25) -> 0
D26: Others | E26: =20000+26990 -> 46990 | G26: 0 | I26: 9000 | K26: 15000 | M26: 0 | O26: =SUM(E26:N26) -> 70990
H29: {=(INDIRECT("I" & ROW() + 1)/INDIRECT("E" & ROW() + 1))} -> #DIV/0! | L29: {=(1 - INDIRECT("I" & ROW()))} -> 1
D30: =O50 -> 965535 | H30: =O35 -> 520128 | K30: =D30-H30 -> 445407
C31: Available to budget | H31: Spent this month | K31: Budgeted this month
C33: February
D34: CATEGORY | E34: WEEK1 | G34: WEEK2 | I34: WEEK3 | K34: WEEK4 | M34: WEEK5 | O34: TOTAL
D35: 🛍️ Expenses | E35: =SUM(E36:F49) -> 143156 | G35: =SUM(G36:H49) -> 268319 | I35: =SUM(I36:J49) -> 68264 | K35: =SUM(K36:L49) -> 40389 | M35: =SUM(M36:M49) -> 0 | O35: =SUM(E35:N35) -> 520128
D36: Rent & bills | E36: 0 | G36: =294021-87010 -> 207011 | I36: 0 | K36: 0 | M36: 0 | O36: =SUM(E36:N36) -> 207011
D37: Groceries | E37: 8105 | G37: =3846+5879+347+600+684+7078+600 -> 19034 | I37: =2714+1000+4074+2188+3385+617+1299+6986 -> 22263 | K37: =2066+2156+1398+550+2330+5111+477+1199+600+4516 -> 20403 | M37: 0 | O37: =SUM(E37:N37) -> 69805
D38: Supplies & home | E38: 0 | G38: =3822+1283 -> 5105 | I38: 0 | K38: 3790 | M38: 0 | O38: =SUM(E38:N38) -> 8895
D39: Dining Out | E39: 0 | G39: =1990+2000 -> 3990 | I39: =2890+4070 -> 6960 | K39: =3490+2000 -> 5490 | M39: 0 | O39: =SUM(E39:N39) -> 16440
D40: Drinking Out | E40: 0 | G40: =1305+990+900 -> 3195 | I40: =1000+1640+1000+940 -> 4580 | K40: =2666+1000+780+2330+1150+940 -> 8866 | M40: 0 | O40: =SUM(E40:N40) -> 16641
D41: Electronics & digital | E41: 0 | G41: 0 | I41: 0 | K41: 0 | M41: 0 | O41: =SUM(E41:N41) -> 0
D42: Health & medicine | E42: 0 | G42: 0 | I42: 0 | K42: 0 | M42: 0 | O42: =SUM(E42:N42) -> 0
D43: Fashion | E43: 0 | G43: 0 | I43: 0 | K43: 0 | M43: 0 | O43: =SUM(E43:N43) -> 0
D44: Vacation | E44: =2200+9108+25000+16643+13720+18380+5915+1473+8220+11527+822+1233+16104+1314+1147 -> 132806 | G44: 0 | I44: 0 | K44: 0 | M44: 0 | O44: =SUM(E44:N44) -> 132806
...

Sheet 2024
H1: {=(INDIRECT("I" & ROW() + 1)/INDIRECT("E" & ROW() + 1))} -> #DIV/0! | L1: {=(1 - INDIRECT("I" & ROW()))} -> 1
D2: =610709+7500 -> 618209 | H2: =O7 -> 468399 | K2: =D2-H2 -> 149810 | M2: 0
C3: Available to budget | H3: Spent this month | K3: Budgeted this month | M3: Pending transactions
C5: January
D6: CATEGORY | E6: WEEK1 | G6: WEEK2 | I6: WEEK3 | K6: WEEK4 | M6: WEEK5 | O6: TOTAL
D7: 🛍️ Expenses | E7: =SUM(E8:F21) -> 22623 | G7: =SUM(G8:H21) -> 275716 | I7: =SUM(I8:J21) -> 31364 | K7: =SUM(K8:L21) -> 111054 | M7: =SUM(M8:M21) -> 27642 | O7: =SUM(E7:N7) -> 468399
D8: Rent & bills | E8: 0 | G8: 206000 | I8: 0 | K8: 0 | M8: 0 | O8: =SUM(E8:N8) -> 206000
D9: Groceries | E9: =8672+710+400+4753+590 -> 15125 | G9: =6229+369+6840+2550+4483+7023 -> 27494 | I9: =7501+403+4254+1524+9428+927 -> 24037 | K9: =4911+899+6938+995+1869 -> 15612 | M9: =7278+2550+7068 -> 16896 | O9: =SUM(E9:N9) -> 99164
D10: Supplies & home | E10: =1088+429+1923 -> 3440 | G10: =300+250+729+8906 -> 10185 | I10: =1599+1578 -> 3177 | K10: =1499+1199+779+15990+600 -> 20067 | M10: 0 | O10: =SUM(E10:N10) -> 36869
D11: Dining Out | E11: 0 | G11: =4048+770 -> 4818 | I11: 0 | K11: 0 | M11: 0 | O11: =SUM(E11:N11) -> 4818
D12: Drinking Out | E12: 3058 | G12: 280 | I12: =1500+2650 -> 4150 | K12: =640+1130+1190 -> 2960 | M12: =1330 -> 1330 | O12: =SUM(E12:N12) -> 11778
D13: Electronics & digital | E13: 0 | G13: 0 | I13: 0 | K13: =33350+14990 -> 48340 | M13: 0 | O13: =SUM(E13:N13) -> 48340
D14: Health & medicine | E14: 0 | G14: =8399+5500 -> 13899 | I14: 0 | K14: 0 | M14: 0 | O14: =SUM(E14:N14) -> 13899
D15: Fashion | E15: 0 | G15: 0 | I15: 0 | K15: 0 | M15: 0 | O15: =SUM(E15:N15) -> 0
D16: Vacation | E16: 0 | G16: 0 | I16: 0 | K16: 0 | M16: 0 | O16: =SUM(E16:N16) -> 0
D17: Transport | E17: 1000 | G17: =450+9500 -> 9950 | I17: 0 | K17: 0 | M17: 0 | O17: =SUM(E17:N17) -> 10950
D18: Subscriptions | E18: 0 | G18: 3090 | I18: 0 | K18: 1830 | M18: 0 | O18: =SUM(E18:N18) -> 4920
D19: Gifts & dates | E19: 0 | G19: 0 | I19: 0 | K19: =18115+1130 -> 19245 | M19: =9416 -> 9416 | O19: =SUM(E19:N19) -> 28661
D20: Entertainment | E20: 0 | G20: 0 | I20: 0 | K20: =(2000+1000) -> 3000 | M20: 0 | O20: =SUM(E20:N20) -> 3000
D21: Others | E21: 0 | G21: 0 | I21: 0 | K21: 0 | M21: 0 | O21: =SUM(E21:N21) -> 0
D22: 💰 Incomes | E22: =SUM(E23:F26) -> 0 | G22: =SUM(H23:H26) -> 0 | I22: =SUM(I23:I26) -> 0 | K22: =SUM(K23:K26) -> 7500 | M22: =SUM(M23:M26) -> 0 | O22: =SUM(E22:N22) -> 7500
D23: Salary | E23: 0 | G23: 0 | I23: 0 | K23: 0 | M23: 0 | O23: =SUM(E23:N23) -> 0
D24: Cafeteria | E24: 0 | H24: 0 | J24: 0 | L24: 0 | M24: 0 | O24: =SUM(E24:N24) -> 0
D25: Gifts | E25: 0 | G25: 0 | I25: 0 | K25: 0 | M25: 0 | O25: =SUM(E25:N25) -> 0
D26: Others | E26: 0 | G26: 0 | I26: 0 | K26: 7500 | M26: 0 | O26: =SUM(E26:N26) -> 7500
H29: {=(INDIRECT("I" & ROW() + 1)/INDIRECT("E" & ROW() + 1))} -> #DIV/0! | L29: {=(1 - INDIRECT("I" & ROW()))} -> 1
D30: =O50 -> 673953 | H30: =O35 -> 590201 | K30: =D30-H30 -> 83752 | M30: 0
C31: Available to budget | H31: Spent this month | K31: Budgeted this month | M31: Pending transactions
C33: February
D34: CATEGORY | E34: WEEK1 | G34: WEEK2 | I34: WEEK3 | K34: WEEK4 | M34: WEEK5 | O34: TOTAL
D35: 🛍️ Expenses | E35: =SUM(E36:F49) -> 21822 | G35: =SUM(G36:H49) -> 269992 | I35: =SUM(I36:J49) -> 247892 | K35: =SUM(K36:L49) -> 39860 | M35: =SUM(M36:M49) -> 10635 | O35: =SUM(E35:N35) -> 590201
D36: Rent & bills | E36: 0 | G36: 203312 | I36: 0 | K36: 0 | M36: 0 | O36: =SUM(E36:N36) -> 203312
D37: Groceries | E37: =2736+1392+3258+4353 -> 11739 | G37: =1887+2367+4468-195+5523+2805 -> 16855 | I37: =398+2851+9686 -> 12935 | K37: =3959+734+449+1757+8856+578 -> 16333 | M37: 999 | O37: =SUM(E37:N37) -> 58861
D38: Supplies & home | E38: 0 | G38: =3046 -> 3046 | I38: 0 | K38: 0 | M38: 998 | O38: =SUM(E38:N38) -> 4044
D39: Dining Out | E39: 0 | G39: =3080+2350 -> 5430 | I39: 804 | K39: 4928 | M39: 0 | O39: =SUM(E39:N39) -> 11162
D40: Drinking Out | E40: 0 | G40: =550+890+(2280-950) -> 2770 | I40: =1850+250 -> 2100 | K40: =2020+1150 -> 3170 | M40: =1144 -> 1144 | O40: =SUM(E40:N40) -> 9184
D41: Electronics & digital | E41: 0 | G41: 0 | I41: =210000+14673 -> 224673 | K41: 13690 | M41: 0 | O41: =SUM(E41:N41) -> 238363
D42: Health & medicine | E42: 4488 | G42: 5000 | I42: 0 | K42: 0 | M42: 0 | O42: =SUM(E42:N42) -> 9488
D43: Fashion | E43: 0 | G43: 0 | I43: 0 | K43: 0 | M43: 1490 | O43: =SUM(E43:N43) -> 1490
D44: Vacation | E44: 0 | G44: 0 | I44: 0 | K44: 0 | M44: 0 | O44: =SUM(E44:N44) -> 0
...

Sheet 2023
A1: eras | I1: {=(INDIRECT("I" & ROW() + 1)/INDIRECT("D" & ROW() + 1))} -> 0.5464238 | M1: {=(1 - INDIRECT("I" & ROW()))} -> 0.4535762
A2: =NOW() -> 46234.098 | D2: =SUM(F22:N22) -> 668097 | I2: =SUM(F7:N7) -> 365064.1 | L2: =D2-I2 -> 303032.9 | N2: 0
A3: Last updated | D3: Available to budget | I3: Spent this month | L3: Budgeted this month | N3: Pending transactions
D5: January
A6: WEEK | B6: LIMITS | E6: CATEGORY | F6: WEEK1 | H6: WEEK2 | J6: WEEK3 | L6: WEEK4 | N6: WEEK5 | P6: TOTAL
A7: #1 | B7: 44932 | E7: 🛍️ Expenses | F7: =SUM(F8:F21) -> 80719 | H7: =SUM(H8:H21) -> 84490 | J7: =SUM(J8:J21) -> 91455 | L7: =SUM(L8:L21) -> 14123 | N7: =SUM(N8:N21) -> 94277.1 | P7: =SUM(F7:O7) -> 365064.1
A8: #2 | B8: 45120 | E8: Rent & bills | F8: 41249 | H8: 0 | J8: 0 | N8: 5680 | P8: =SUM(F8:O8) -> 46929
A9: #3 | B9: 14-20 | E9: Groceries | F9: =(6699-1700+1166) -> 6165 | H9: =2493+550+10977-3700-947+5870 -> 15243 | J9: =12517-5790+700+1428 -> 8855 | L9: =2475+580+1968 -> 5023 | N9: 700 | P9: =SUM(F9:O9) -> 35986
A10: #4 | B10: 21-27 | E10: Supplies & home | F10: 0 | H10: 1090 | J10: 0 | L10: =400+7100-3850 -> 3650 | N10: 0 | P10: =SUM(F10:O10) -> 4740
A11: #5 | B11: 28-31 | E11: Dining Out | F11: 4800 | H11: 0 | J11: =6420+2130+2450 -> 11000 | L11: 0 | N11: 0 | P11: =SUM(F11:O11) -> 15800
E12: Drinking Out | F12: 0 | H12: 0 | J12: 0 | L12: 0 | N12: 0 | P12: =SUM(F12:O12) -> 0
E13: Electronics & digital | F13: =7197+790 -> 7987 | H13: 43480 | J13: 0 | L13: 0 | N13: 0 | P13: =SUM(F13:O13) -> 51467
E14: Health & medicine | F14: 0 | H14: 0 | J14: 70000 | L14: =3850 -> 3850 | N14: 2608 | P14: =SUM(F14:O14) -> 76458
E15: Fashion | F15: 0 | H15: 0 | J15: 0 | L15: 0 | N15: 0 | P15: =SUM(F15:O15) -> 0
E16: Vacation | F16: 0 | H16: 0 | J16: 0 | L16: 0 | N16: =(20+1.44+8.41+4.18+8.9+1.45+1.45+5.7+9.95+6.95+15.5+0.63+30+8.3+5.2+37+4.4+27.35+3.53+5.95+4.4+3+5)*390 -> 85289.1 | P16: =SUM(F16:O16) -> 85289.1
E17: Transport | F17: 16048 | H17: 9500 | J17: 0 | L17: 0 | N17: 0 | P17: =SUM(F17:O17) -> 25548
E18: Subscriptions | F18: 0 | H18: 0 | J18: 1600 | L18: 1600 | N18: 0 | P18: =SUM(F18:O18) -> 3200
E19: Gifts | F19: 4470 | H19: 0 | J19: 0 | L19: 0 | N19: 0 | P19: =SUM(F19:O19) -> 4470
E20: Entertainment | F20: 0 | H20: 1500 | J20: 0 | L20: 0 | N20: 0 | P20: =SUM(F20:O20) -> 1500
E21: Others | F21: 0 | H21: 13677 | J21: 0 | L21: 0 | N21: 0 | P21: =SUM(F21:O21) -> 13677
E22: 💰 Incomes | F22: =SUM(F23:F26) -> 668097 | H22: =SUM(H23:H26) -> 0 | J22: =SUM(K23:K26) -> 0 | L22: =SUM(L23:L26) -> 0 | N22: =SUM(N23:N26) -> 0 | P22: =SUM(F22:O22) -> 668097
E23: Salary | F23: 668097 | H23: 0 | J23: 0 | L23: 0 | N23: 0 | P23: =SUM(F23:O23) -> 668097
E24: Cafeteria | F24: 0 | I24: 0 | K24: 0 | M24: 0 | N24: 0 | P24: =SUM(F24:O24) -> 0
E25: Gifts | F25: 0 | H25: 0 | J25: 0 | L25: 0 | N25: 0 | P25: =SUM(F25:O25) -> 0
E26: Others | F26: 0 | H26: 0 | J26: 0 | L26: 0 | N26: 0 | P26: =SUM(F26:O26) -> 0
I29: {=(INDIRECT("I" & ROW() + 1)/INDIRECT("D" & ROW() + 1))} -> 0.48433081 | M29: {=(1 - INDIRECT("I" & ROW()))} -> 0.51566919
D30: =SUM(F50:N50) -> 679550 | I30: =SUM(F35:N35) -> 329127 | L30: =D30-I30 -> 350423 | N30: 0
D31: Available to budget | I31: Spent this month | L31: Budgeted this month | N31: Pending transactions
D33: February
A34: WEEK | B34: LIMITS | E34: CATEGORY | F34: WEEK1 | H34: WEEK2 | J34: WEEK3 | L34: WEEK4 | N34: WEEK5 | P34: TOTAL
A35: #1 | B35: 44932 | E35: 🛍️ Expenses | F35: =SUM(F36:F49) -> 30431 | H35: =SUM(H36:H49) -> 172647 | J35: =SUM(J36:J49) -> 105400 | L35: =SUM(L36:L49) -> 16314 | N35: =SUM(N36:N49) -> 4335 | P35: =SUM(F35:O35) -> 329127
A36: #2 | B36: 45120 | E36: Rent & bills | F36: 0 | H36: =119957+5680 -> 125637 | J36: 0 | L36: 0 | N36: 0 | P36: =SUM(F36:O36) -> 125637
A37: #3 | B37: 14-20 | E37: Groceries | F37: =4039+5558+620+1884 -> 12101 | H37: =729+2903+1056+1604+620+2048 -> 8960 | J37: =2364+5192+497+620+669+4310 -> 13652 | L37: =2061+570+620+2675+1399+269+600+580 -> 8774 | N37: 1790 | P37: =SUM(F37:O37) -> 45277
A38: #4 | B38: 21-27 | E38: Supplies & home | F38: 0 | H38: =1570+3197+4790 -> 9557 | J38: =1900+6990+938 -> 9828 | L38: 1250 | N38: 0 | P38: =SUM(F38:O38) -> 20635
A39: #5 | B39: 28-31 | E39: Dining Out | F39: =1270+2250 -> 3520 | H39: =1790+4850+2610+2140 -> 11390 | J39: =2190+2400+2190 -> 6780 | L39: =2045+2645 -> 4690 | N39: 2545 | P39: =SUM(F39:O39) -> 28925
E40: Drinking Out | F40: 0 | H40: 2180 | J40: 2500 | L40: 0 | N40: 0 | P40: =SUM(F40:O40) -> 4680
E41: Electronics & digital | F41: 3790 | H41: 0 | J41: 0 | L41: 0 | N41: 0 | P41: =SUM(F41:O41) -> 3790
E42: Health & medicine | F42: 5000 | H42: 0 | J42: 70000 | L42: 0 | N42: 0 | P42: =SUM(F42:O42) -> 75000
E43: Fashion | F43: 0 | H43: 0 | J43: 0 | L43: 0 | N43: 0 | P43: =SUM(F43:O43) -> 0
E44: Vacation | F44: 0 | H44: 0 | J44: 0 | L44: 0 | N44: 0 | P44: =SUM(F44:O44) -> 0
...

Sheet 2022
A1: I spent this much money on this kinda shit
H3: Hónap | I3: JAN | N3: FEB | S3: MÁR | X3: ÁPR
B4: Code | C4: Description | H4: Hét | I4: 1 | J4: 2 | K4: 3 | L4: 4 | M4: 5 | N4: 1 | O4: 2 | P4: 3 | Q4: 4 | R4: 5 | S4: 1 | T4: 2 | U4: 3 | V4: 4 | W4: 5 | X4: 1 | Y4: 2 | Z4: 3 | AA4: 4 | AB4: 5
B5: A | C5: rent+utilities | I5: 55000 | N5: 110000 | S5: =600+600 -> 1200 | X5: 600 | AB5: 86
B6: B | C6: basic food and stuff | I6: =4474+8449 -> 12923 | J6: =1939+280 -> 2219 | K6: =3970+280+1807 -> 6057 | L6: =712+1279+774+2330 -> 5095 | M6: =5488 -> 5488 | N6: =500+1600+778 -> 2878 | O6: =3895+1368+636+547 -> 6446 | P6: =2030+780+1685+1292+399+280 -> 6466 | Q6: =866 -> 866 | R6: =(31+14.38+47.14+8.07+134.16 - 50)*73 -> 13486.75 | S6: =23+10+3.99+2.89+6.2+(120-26+9.88) -> 149.96 | T6: =57+6.5+5+9.5+9.65+6.5 -> 94.15 | U6: =5.35+(112.5-35.57-10)+(2.9+8.93)+(28.77+18.42) -> 131.3 | V6: =3.89+(55.21+38.4-26)+(6.25+51.37) -> 129.12 | W6: =30.54+1+6.99+6.42+10.28+7.7+7.5 -> 70.43 | X6: =16.97+16+31.86+4.99+6+16+11.86+94.74 -> 198.42 | Y6: =4.3+18.16 -> 22.46 | Z6: =3.4+9.38+46.22+32.25 -> 91.25 | AA6: =10.28+3.4 -> 13.68 | AB6: =1+4+26.3 -> 31.3
B7: C | C7: sweets/junk food | M7: =789+159+539+359 -> 1846 | O7: 2500 | P7: 1442 | R7: =5*73 -> 365 | S7: 30 | U7: =6.15+(8+2)+2 -> 18.15 | V7: 24.9 | AA7: 3
B8: D | C8: ordered food/going out | J8: 1700 | K8: =890+890 -> 1780 | L8: 2000 | M8: =530+1975 -> 2505 | N8: =1800+430+460 -> 2690 | O8: =550+1600+590+1800 -> 4540 | P8: =1190+800 -> 1990 | R8: =27*73 -> 1971 | S8: =16.95 -> 16.95 | V8: 10 | AA8: =22 -> 22
B9: E | C9: electronics & tools | R9: =50*73 -> 3650 | U9: =(600+300+20) -> 920 | V9: =1331+1024 -> 2355 | W9: =1770+15+25+12 -> 1822 | Y9: 300
B10: F | C10: clothes | T10: =54.99+34.99 -> 89.98
B11: G | C11: gifts | O11: 20749 | S11: 77 | W11: 40 | X11: =17+23 -> 40 | Z11: 55
B12: H | C12: transport, traveling | I12: 3450 | N12: 3450 | R12: =8000+((2+2+2)*73) -> 8438 | S12: =4+2 -> 6 | T12: =2+2+2 -> 6 | U12: =2+2 -> 4 | V12: =2+2+(2+2) -> 8 | W12: =2 -> 2 | Y12: =11+25+(5+5)+25+(2+2) -> 75 | Z12: =12+3+4 -> 19 | AB12: 50
B13: I | C13: others (vacation, crypto, entertainment, skincare, etc.) | K13: =(300.35+259.81+5+29.45+108.86+47.01+9.9+39.59+64)*73 -> 63069.81 | P13: 495 | Q13: 450 | S13: =55+(32+32+32-32) -> 119 | V13: 81 | AB13: =10+10 -> 20
B14: J | C14: services - dentist, doctor, barber, football,eyecare | I14: 1000 | J14: =1000+3000 -> 4000 | N14: 1000 | O14: 1000 | P14: 1000 | Q14: =3000+1000 -> 4000 | R14: =(320*73) -> 23360 | AA14: 45
B15: K | C15: savings | I15: 222000 | N15: 252101 | R15: 90000 | T15: 3510 | X15: 3510 | AB15: 400
B16: X | C16: out | R16: new frame
B17: Y | C17: in
B18: Z | C18: total
B19: Constants every month:
B20: Netflix | C20: 10
B21: YOXO | C21: 16
I23: MÁJ | N23: JÚN | S23: JÚL | X23: AUG
I24: 1 | J24: 2 | K24: 3 | L24: 4 | M24: 5 | N24: 1 | O24: 2 | P24: 3 | Q24: 4 | R24: 5 | S24: 1 | T24: 2 | U24: 3 | V24: 4 | W24: 5 | X24: 1 | Y24: 2 | Z24: 3 | AA24: 4 | AB24: 5
H25: rent+utilities | I25: 600 | J25: 200 | N25: =600+92.2 -> 692.2 | P25: 81.5 | S25: =28+600+63 -> 691 | T25: 124.8 | U25: =32 -> 32 | X25: 383.84 | Y25: 1200 | AB25: =207250/84 + 260.9 + 485.84 -> 3214.0019
H26: basic food and stuff | I26: =4.9+8.42+57.55+8.98 -> 79.85 | J26: =8.38+16.02+(60.2+11.79)+2.7 -> 99.09 | K26: =40.74+(7.77+30.59)+3.9 -> 83 | L26: =(10+57+8) -> 75 | M26: =(3.15+20.5)+(37.5)+(7.58)+80.84 -> 149.57 | N26: =3.15+(77.94+13.55) -> 94.64 | O26: =17.84+3.15+(2.99+86.52) -> 110.5 | P26: =(3.15+34.4+6.87+(3.15+48.34+28.91)) -> 124.82 | Q26: =(11)+(3.15+(5.95+7.11))+15.87+105+(7+2) -> 157.08 | R26: =(26.93+127.28+12.3+3.15-62) -> 107.66 | S26: =(81.11+10.88-20)+(3.15+16.4) -> 91.54 | T26: =(79.3+33.17-40.72+11.07)+3.15+((47.59+11.76-7)+1) -> 139.32 | U26: =(3.15+11.5)+(3.15+7.6)+(93.04-6.49+12.38-23) -> 101.33 | V26: 40.45 | Z26: =(132.08-50-57) -> 25.08 | AB26: =((2168+22459-8392+2440)+(5406-1600)+(5140+2630-3928))/84 -> 313.36905
H27: sweets/junk food | M27: 7 | P27: =4+22 -> 26 | Q27: =4+(5.09+1.09+1.09) -> 11.27 | U27: =4+6.49 -> 10.49 | V27: =51.39+7.95+27.53+31.34 -> 118.21 | X27: 6
H28: ordered food/eating out | M28: =(22+15.5)+23 -> 60.5 | N28: =13+4.4 -> 17.4 | O28: 33 | Q28: 40 | Z28: =47 -> 47 | AA28: =(7+3.5) -> 10.5 | AB28: =2080/84 -> 24.761905
H29: electronics & supplies | M29: 145 | O29: 83 | Z29: 50 | AB29: =(5275+550-2500)/84 -> 39.583333
H30: clothes | R30: 48.57 | AB30: =3495/84 -> 41.607143
H31: gifts | P31: 65 | Z31: 34
H32: transport | J32: 2 | K32: =2+30 -> 32 | L32: =30+(2+2) -> 34 | M32: 2 | N32: =(25+25)+2+2 -> 54 | O32: =2+2 -> 4 | P32: =(2+5)+2 -> 9 | R32: 21 | S32: 6 | T32: =2+(5+2) -> 9 | U32: =5+2+2 -> 9 | W32: 10 | Y32: =115+31+10 -> 156 | Z32: =(280+5+5) -> 290 | AA32: =(5+5) -> 10 | AB32: =(2530+3000+8800)/84 -> 170.59524
H33: others (entertainment, crypto, etc.) | I33: 17 | N33: 50 | R33: 100 | S33: 30
H34: services(doctor, dentist, barber, massage, courses) | J34: 20 | K34: 3 | L34: 3 | O34: 40 | P34: 70 | T34: =(3+3)+13 -> 19 | U34: 3 | Z34: =(80+40) -> 120 | AB34: =(3000+1000)/84 -> 47.619048
H35: savings | I35: 3510 | J35: 110 | L35: 400 | O35: 3510 | Q35: 142 | T35: 3510 | X35: =(4000+1000) -> 5000 | Y35: =200 -> 200 | Z35: 3565
H36: X | X36: bonusz | Y36: foglalora | AB36: 2ho kaucio+kozk.
H37: Y | Y37: plusz 8k huf+100eur | AB37: bolt+vonat pragaba
H38: Z | AB38: telekom 3k
H42: 84.07 | I42: FORINT
H43: BUDAPEST | I43: SZEP | N43: OKT | S43: NOV | X43: DEC
I44: 1 | J44: 2 | K44: 3 | L44: 4 | M44: 5 | N44: 1 | O44: 2 | P44: 3 | Q44: 4 | R44: 5 | S44: 1 | T44: 2 | U44: 3 | V44: 4 | W44: 5 | X44: 1 | Y44: 2 | Z44: 3 | AA44: 4 | AB44: 5
H45: 1RON TO HUF | I45: 84 | J45: 81 | K45: 83 | L45: 82.2 | M45: 85.26 | N45: 85 | O45: 85.96 | P45: 83 | Q45: 83.36 | R45: 83.75 | S45: 82.72 | T45: 82.81 | U45: 82.27 | V45: 83.24 | W45: 82.97 | X45: 83.15 | Y45: 85.03 | Z45: 82.61 | AA45: 82.2 | AB45: 81.33
...

Sheet 2021
A1: I spent this much money on this kinda shit
H3: Hónap | I3: JAN | N3: FEB | S3: MÁR | X3: ÁPR
B4: Code | C4: Description | H4: Hét | I4: 1 | J4: 2 | K4: 3 | L4: 4 | M4: 5 | N4: 1 | O4: 2 | P4: 3 | Q4: 4 | R4: 5 | S4: 1 | T4: 2 | U4: 3 | V4: 4 | W4: 5 | X4: 1 | Y4: 2 | Z4: 3 | AA4: 4 | AB4: 5
B5: A | C5: rent+utilities | I5: 320 | J5: 53 | K5: 100 | L5: 30 | N5: 320 | O5: 50 | P5: 20 | Q5: 39 | S5: 323 | T5: 100 | U5: 92 | X5: 328 | Y5: 50 | Z5: 45
B6: B | C6: basic food and stuff | I6: 157 | J6: 8 | K6: 100 | L6: 30 | M6: 3 | N6: 30 | O6: 26 | P6: 60 | Q6: 86 | R6: 83 | S6: 44 | T6: 199 | U6: 45 | V6: 37 | W6: 57 | X6: 83 | Y6: 71 | Z6: 44 | AA6: 77 | AB6: 103
B7: C | C7: sweets/junk food | I7: 10 | U7: 0 | Z7: 13 | AB7: 10
B8: D | C8: ordered food | I8: 70 | J8: 20 | K8: 31 | N8: 33 | P8: 66 | R8: 63 | S8: 33 | T8: 25
B9: E | C9: electronics | I9: 160 | J9: 2322 | N9: 50 | O9: 50 | S9: 560 | Z9: 50
B10: F | C10: clothes | I10: 60 | N10: 45 | R10: 56 | U10: 0 | AB10: 167
B11: G | C11: gifts | R11: 86
B12: H | C12: transport | X12: 92 | AA12: 8
B13: I | C13: others (crypto, entertainment, skincare, etc.)
B14: J | C14: dentist, doctor, barber
B15: K | C15: savings | I15: 1500 | J15: 320 | N15: 100 | P15: 1500 | Q15: 800 | S15: 27 | T15: 100 | U15: 800 | V15: 1500 | X15: 50 | Y15: 1500 | Z15: 800
B16: X | C16: out | S16: AOC Monitor | X16: husvet
B17: Y | C17: in | R17: Ebay adidas hoodie | AB17: NED88 mez
B18: Z | C18: total
B19: Constants every month:
B20: Netflix | C20: 10
B21: YOXO | C21: 16
I23: MÁJ | N23: JÚN | S23: JÚL | X23: AUG
I24: 1 | J24: 2 | K24: 3 | L24: 4 | M24: 5 | N24: 1 | O24: 2 | P24: 3 | Q24: 4 | R24: 5 | S24: 1 | T24: 2 | U24: 3 | V24: 4 | W24: 5 | X24: 1 | Y24: 2 | Z24: 3 | AA24: 4 | AB24: 5
H25: rent+utilities | I25: 328 | J25: 69 | N25: 329 | O25: 86 | R25: 88 | S25: 340 | T25: 87 | X25: 340 | Y25: 87 | AA25: =0*0.014 -> 0 | AB25: =11000*0.014 -> 154
H26: basic food and stuff | I26: 92 | J26: 74 | K26: 62 | L26: 97 | M26: 107 | N26: 66 | O26: =55+10+10+5+15.8 -> 95.8 | P26: =3+62 -> 65 | Q26: 48 | S26: =3+8.4 -> 11.4 | T26: =90+27 -> 117 | V26: =86+10+20 -> 116 | W26: =92+10 -> 102 | X26: =37+18+36 -> 91 | Y26: =62+25+10+18.38+35 -> 150.38 | Z26: =46 -> 46 | AA26: =0*0.014 -> 0 | AB26: =(2685+750+3570)*0.014 -> 98.07
H27: sweets/junk food | K27: 10 | L27: 5 | M27: 16.5 | T27: 8 | Z27: 15 | AA27: =0*0.014 -> 0 | AB27: =(2250+258)*0.014 -> 35.112
H28: ordered food | O28: 31 | P28: 34 | Q28: 42 | T28: 34 | V28: 22 | Y28: =6+29 -> 35 | Z28: 35 | AA28: =0*0.014 -> 0 | AB28: =0*0.014 -> 0
H29: electronics | L29: 45 | V29: =2600+160 -> 2760 | AA29: =0*0.014 -> 0 | AB29: =0/0.014 -> 0
H30: clothes | M30: =34+40 -> 74 | O30: 25 | Q30: =24+52 -> 76 | X30: 25.5 | Z30: =70 -> 70 | AA30: =0*0.014 -> 0 | AB30: =0/0.014 -> 0
H31: gifts | M31: 40 | AA31: =0*0.014 -> 0 | AB31: =0/0.014 -> 0
H32: transport | J32: 30 | N32: 8 | W32: 80 | Y32: 22 | Z32: =30+25 -> 55 | AA32: 0 | AB32: 0
H33: others (crypto, etc.) | J33: 50 | O33: =50+30 -> 80 | P33: 305 | U33: 48 | V33: =110+86+71 -> 267 | AA33: 0 | AB33: 0
H34: services(doctor, dentist, barber, massage) | Y34: =220+200 -> 420 | AA34: =0*0.014 -> 0 | AB34: 30
H35: savings | J35: 1000 | K35: 1500 | N35: 1500 | O35: 1000 | S35: 1500 | T35: 800 | Y35: 300 | Z35: 1500 | AA35: 800 | AB35: 950
H36: X | J36: ETDK | V36: Iphone 12 mini + chargers | AB36: BP szallas
H37: Y | AB37: roaming
H38: Z
H42: 72 | I42: FORINT
H43: BUDAPEST | I43: SZEP | N43: OKT | S43: NOV | X43: DEC
I44: 1 | J44: 2 | K44: 3 | L44: 4 | M44: 5 | N44: 1 | O44: 2 | P44: 3 | Q44: 4 | R44: 5 | S44: 1 | T44: 2 | U44: 3 | V44: 4 | W44: 5 | X44: 1 | Y44: 2 | Z44: 3 | AA44: 4 | AB44: 5
H45: rent+utilities | I45: 55000 | N45: =45000+10000 -> 55000 | S45: 55000 | X45: 55000
...

Sheet Assets
A2: Name | B2: Type | C2: Value | D2: Currency | H2: Currency | I2: EUR Rate
A3: Revolut EUR | B3: Savings | C3: 713.33 | D3: EUR | H3: RON | I3: 0.2
A4: Revolut RON | B4: Spending | C4: 7263.42 | D4: RON | H4: HUF | I4: 0.0025
A5: Revolut HUF | B5: Spending | C5: 6380.56 | D5: HUF | H5: USD | I5: 1
A6: OTP RON | B6: Void | C6: 7733.86 | D6: RON
A7: ERSTE HUF | B7: Salary | C7: 521942 | D7: HUF
A8: Binance | B8: Crypto | C8: 14.2 | D8: USD
A9: Trade212 | B9: Invest | C9: 102.78 | D9: RON
A10: Total | B10: - | C10: =SUMIF($D$3:$D$9,D10,$C$3:$C$9) -> 713.33 | D10: EUR
C11: =SUMIF($D$3:$D$9,D11,$C$3:$C$9) -> 528322.56 | D11: HUF
C12: =SUMIF($D$3:$D$9,D12,$C$3:$C$9) -> 7836.64 | D12: RON
C13: =(C10 + C11*I4 + C12*I3) -> 3601.4644 | D13: ALL

Sheet Investments
B2: Investments
B3: Funds & Stocks Portfolio
B4: Type | C4: Exchange | D4: Region | E4: Currency | G4: Name | H4: Ticker | I4: # | J4: ACC | K4: Invested (USD) | L4: Invested (EUR) | M4: Value (EUR) | N4: Value (USD) | O4: Gain (%) | P4: % | Q4: Price (EUR) | R4: Price (USD)
B5: STOCK | C5: NASDAQ | D5: USA | E5: =IFERROR(__xludf.DUMMYFUNCTION("IF(ISBLANK(H5), ""-"", GOOGLEFINANCE(IF(ISBLANK(C5), H5, C5&"":""&H5), ""currency""))"),"USD") -> USD | G5: Apple | H5: AAPL | I5: 4.1868055 | J5: - | K5: =(4.058092893* 179.96+0.128712567*186.24) -> 754.26583 | L5: =K5*E18 -> 655.01199 | M5: =I5*Q5 -> 1212.306 | N5: =I5*R5 -> 1396.0065 | O5: =if(K5=0,0,(N5-K5)/K5) -> 0.85081505 | P5: =M5/($I17) -> 0.19314432 | Q5: =IFERROR(__xludf.DUMMYFUNCTION("if(E5 = ""USD"",R5*GoogleFinance(""CURRENCY:USDEUR""),GOOGLEFINANCE(IF(ISBLANK(C5), H5, C5&"":""&H5), ""Price""))"),289.5539463) -> 289.55395 | R5: =IFERROR(__xludf.DUMMYFUNCTION("if(E5 = ""USD"",GOOGLEFINANCE(IF(ISBLANK(C5), H5, C5&"":""&H5), ""Price""),Q5*GoogleFinance(""CURRENCY:EURUSD""))"),333.43) -> 333.43
B6: STOCK | C6: NASDAQ | D6: USA | E6: =IFERROR(__xludf.DUMMYFUNCTION("IF(ISBLANK(H6), ""-"", GOOGLEFINANCE(IF(ISBLANK(C6), H6, C6&"":""&H6), ""currency""))"),"USD") -> USD | G6: NVidia | H6: NVDA | I6: 0.9780213 | J6: - | K6: =(0.099779546*660.46 + 0.878241758*682.5) -> 665.3004 | L6: =K6*E18 -> 577.75352 | M6: =I6*Q6 -> 165.65205 | N6: =I6*R6 -> 190.75328 | O6: =if(K6=0,0,(N6-K6)/K6) -> -0.71328249 | P6: =M6/I17 -> 0.026391646 | Q6: =IFERROR(__xludf.DUMMYFUNCTION("if(E6 = ""USD"",R6*GoogleFinance(""CURRENCY:USDEUR""),GOOGLEFINANCE(IF(ISBLANK(C6), H6, C6&"":""&H6), ""Price""))"),169.3746864) -> 169.37469 | R6: =IFERROR(__xludf.DUMMYFUNCTION("if(E6 = ""USD"",GOOGLEFINANCE(IF(ISBLANK(C6), H6, C6&"":""&H6), ""Price""),Q6*GoogleFinance(""CURRENCY:EURUSD""))"),195.04) -> 195.04
B7: STOCK | C7: NYSE | D7: EU | E7: =IFERROR(__xludf.DUMMYFUNCTION("IF(ISBLANK(H7), ""-"", GOOGLEFINANCE(IF(ISBLANK(C7), H7, C7&"":""&H7), ""currency""))"),"USD") -> USD | G7: Novo Nordisk | H7: NVO | I7: 3.41659 | J7: - | K7: =(1.716642323 * 116.39 + 1.623371113*117.82 + 0.076576576 * 118.41) -> 400.13302 | L7: =K7*E18 -> 347.47951 | M7: =I7*Q7 -> 153.12692 | N7: =I7*R7 -> 176.33021 | O7: =if(K7=0,0,(N7-K7)/K7) -> -0.55932102 | P7: =M7/I17 -> 0.024396145 | Q7: =IFERROR(__xludf.DUMMYFUNCTION("if(E7 = ""USD"",R7*GoogleFinance(""CURRENCY:USDEUR""),GOOGLEFINANCE(IF(ISBLANK(C7), H7, C7&"":""&H7), ""Price""))"),44.8186401) -> 44.81864 | R7: =IFERROR(__xludf.DUMMYFUNCTION("if(E7 = ""USD"",GOOGLEFINANCE(IF(ISBLANK(C7), H7, C7&"":""&H7), ""Price""),Q7*GoogleFinance(""CURRENCY:EURUSD""))"),51.61) -> 51.61
B8: STOCK | C8: NYSE | D8: EU | E8: =IFERROR(__xludf.DUMMYFUNCTION("IF(ISBLANK(H8), ""-"", GOOGLEFINANCE(IF(ISBLANK(C8), H8, C8&"":""&H8), ""currency""))"),"USD") -> USD | G8: Spotify | H8: SPOT | I8: =0.053302062+0.145933266 -> 0.19923533 | J8: - | K8: =(0.053302062*187.61)+(0.145933266*231.34) -> 43.760202 | L8: =9.29+33.86 -> 43.15 | M8: =I8*Q8 -> 90.420911 | N8: =I8*R8 -> 104.12237 | O8: =if(K8=0,0,(N8-K8)/K8) -> 1.3793852 | P8: =M8/I17 -> 0.014405839 | Q8: =IFERROR(__xludf.DUMMYFUNCTION("if(E8 = ""USD"",R8*GoogleFinance(""CURRENCY:USDEUR""),GOOGLEFINANCE(IF(ISBLANK(C8), H8, C8&"":""&H8), ""Price""))"),453.8397501) -> 453.83975 | R8: =IFERROR(__xludf.DUMMYFUNCTION("if(E8 = ""USD"",GOOGLEFINANCE(IF(ISBLANK(C8), H8, C8&"":""&H8), ""Price""),Q8*GoogleFinance(""CURRENCY:EURUSD""))"),522.61) -> 522.61
B9: ETF | C9: BIT | D9: EU | E9: =IFERROR(__xludf.DUMMYFUNCTION("IF(ISBLANK(H9), ""-"", GOOGLEFINANCE(IF(ISBLANK(C9), H9, C9&"":""&H9), ""currency""))"),"EUR") -> EUR | G9: Vanguard FTSE All World | H9: VWCE | I9: =16+15+1+5+4 -> 41 | J9: 228.14 | K9: =L9*1.08 -> 4988.8332 | L9: =(3*111.9+12*112.02+1*112+15*112.54+112.55+5*112.54+4*116) -> 4619.29 | M9: =L9+J9 -> 4847.43 | N9: =IFERROR(__xludf.DUMMYFUNCTION("M9*GoogleFinance(""CURRENCY:EURUSD"")"),5581.8641193) -> 5581.8641 | O9: =if(K9=0,0,(N9-K9)/K9) -> 0.11887167 | P9: =M9/I17 -> 0.77229142 | Q9: =IFERROR(__xludf.DUMMYFUNCTION("if(E9 = ""USD"",R9*GoogleFinance(""CURRENCY:USDEUR""),GOOGLEFINANCE(IF(ISBLANK(C9), H9, C9&"":""&H9), ""Price""))"),164.24) -> 164.24 | R9: =IFERROR(__xludf.DUMMYFUNCTION("if(E9 = ""USD"",GOOGLEFINANCE(IF(ISBLANK(C9), H9, C9&"":""&H9), ""Price""),Q9*GoogleFinance(""CURRENCY:EURUSD""))"),189.12400240000002) -> 189.124
H10: CSPX | I10: 0 | K10: 0 | L10: =IFERROR(__xludf.DUMMYFUNCTION("K10*GoogleFinance(""CURRENCY:USDEUR"")"),0.0) -> 0 | M10: =I10*Q10 -> 0 | N10: =I10*R10 -> 0 | O10: =if(K10=0,0,(N10-K10)/K10) -> 0 | P10: =M10/I17 -> 0 | Q10: =IFERROR(__xludf.DUMMYFUNCTION("if(E10 = ""USD"",R10*GoogleFinance(""CURRENCY:USDEUR""),GOOGLEFINANCE(IF(ISBLANK(C10), H10, C10&"":""&H10), ""Price""))"),806.29) -> 806.29 | R10: =IFERROR(__xludf.DUMMYFUNCTION("if(E10 = ""USD"",GOOGLEFINANCE(IF(ISBLANK(C10), H10, C10&"":""&H10), ""Price""),Q10*GoogleFinance(""CURRENCY:EURUSD""))"),928.4509979) -> 928.451
H11: IWDA | I11: 0 | K11: 0 | L11: =IFERROR(__xludf.DUMMYFUNCTION("K11*GoogleFinance(""CURRENCY:USDEUR"")"),0.0) -> 0 | M11: =I11*Q11 -> 0 | N11: =I11*R11 -> 0 | O11: =if(K11=0,0,(N11-K11)/K11) -> 0 | P11: =M11/I17 -> 0 | Q11: =IFERROR(__xludf.DUMMYFUNCTION("if(E11 = ""USD"",R11*GoogleFinance(""CURRENCY:USDEUR""),GOOGLEFINANCE(IF(ISBLANK(C11), H11, C11&"":""&H11), ""Price""))"),144.08) -> 144.08 | R11: =IFERROR(__xludf.DUMMYFUNCTION("if(E11 = ""USD"",GOOGLEFINANCE(IF(ISBLANK(C11), H11, C11&"":""&H11), ""Price""),Q11*GoogleFinance(""CURRENCY:EURUSD""))"),165.9095608) -> 165.90956
H12: VUAA | I12: 0 | K12: 0 | L12: =IFERROR(__xludf.DUMMYFUNCTION("K12*GoogleFinance(""CURRENCY:USDEUR"")"),0.0) -> 0 | M12: =I12*Q12 -> 0 | N12: =I12*R12 -> 0 | O12: =if(K12=0,0,(N12-K12)/K12) -> 0 | P12: =M12/I17 -> 0 | Q12: =IFERROR(__xludf.DUMMYFUNCTION("if(E12 = ""USD"",R12*GoogleFinance(""CURRENCY:USDEUR""),GOOGLEFINANCE(IF(ISBLANK(C12), H12, C12&"":""&H12), ""Price""))"),144.64) -> 144.64 | R12: =IFERROR(__xludf.DUMMYFUNCTION("if(E12 = ""USD"",GOOGLEFINANCE(IF(ISBLANK(C12), H12, C12&"":""&H12), ""Price""),Q12*GoogleFinance(""CURRENCY:EURUSD""))"),166.55440639999998) -> 166.55441
H13: META | I13: 0 | K13: 0 | L13: =IFERROR(__xludf.DUMMYFUNCTION("K13*GoogleFinance(""CURRENCY:USDEUR"")"),0.0) -> 0 | M13: =I13*R13 -> 0 | N13: =I13*R13 -> 0 | O13: =if(K13=0,0,(N13-K13)/K13) -> 0 | P13: =M13/I17 -> 0 | Q13: =IFERROR(__xludf.DUMMYFUNCTION("if(E13 = ""USD"",R13*GoogleFinance(""CURRENCY:USDEUR""),GOOGLEFINANCE(IF(ISBLANK(C13), H13, C13&"":""&H13), ""Price""))"),539.03) -> 539.03 | R13: =IFERROR(__xludf.DUMMYFUNCTION("if(E13 = ""USD"",GOOGLEFINANCE(IF(ISBLANK(C13), H13, C13&"":""&H13), ""Price""),Q13*GoogleFinance(""CURRENCY:EURUSD""))"),620.6984353) -> 620.69844
E14: EUR | G14: CASH | H14: - | I14: 1 | K14: =L14*F17 -> 39.15134 | L14: 34 | M14: 34 | N14: =IFERROR(__xludf.DUMMYFUNCTION("L14*GoogleFinance(""CURRENCY:EURUSD"")"),39.151340000000005) -> 39.15134 | O14: 0 | P14: =M14/$I17 -> 0.0054168721 | Q14: =M14 -> 34 | R14: =IFERROR(__xludf.DUMMYFUNCTION("Q14*GoogleFinance(""CURRENCY:EURUSD"")"),39.151340000000005) -> 39.15134
I15: Summary
E16: EUR | F16: USD | H16: Total | I16: Gains 💪🏻💸 | O16: Growth 🕑
E17: 1 | F17: =IFERROR(__xludf.DUMMYFUNCTION("E17*GoogleFinance(""CURRENCY:EURUSD"")"),1.15151) -> 1.15151 | H17: Invested | I17: =SUM(L5:L14) -> 6276.685 | O17: 1
E18: =IFERROR(__xludf.DUMMYFUNCTION("F18*GoogleFinance(""CURRENCY:USDEUR"")"),0.86841) -> 0.86841 | F18: 1 | H18: Value | I18: =SUM(M5:M14) -> 6502.9359 | O18: =I18/I17 -> 1.0360462
H19: Gained | I19: =I18-I17 -> 226.25091 | O19: =O18-O17 -> 0.036046242
U22: ACCUMULATED GAINS | AH22: RECURRING INVESTMENT | AI22: EXP. GROWTH /MONTH (%)
T23: TOTAL | U23: JAN | V23: FEB | W23: MAR | X23: APR | Y23: MAY | Z23: JUN | AA23: JUL | AB23: AUG | AC23: SEP | AD23: OCT | AE23: NOV | AF23: DEC | AH23: 800 | AI23: 2.5
T24: invested | U24: 739 | V24: =5905 -> 5905 | W24: =I17 -> 6276.685 | X24: =I17 -> 6276.685 | Y24: =8309-613 -> 7696 | Z24: 8309 | AA24: =7322+1000 -> 8322 | AB24: =8799+980 -> 9779 | AC24: =AB26+$AH23 -> 10823.475 | AD24: =AC26+$AH23 -> 11894.062 | AE24: =AD26+$AH23 -> 12991.413 | AF24: =AE26+$AH23 -> 14116.199
T25: reached | U25: 751.69 | V25: 6100 | W25: 6817 | X25: =I18 -> 6502.9359 | Y25: 8200 | Z25: 8309 | AA25: =1433+7761 -> 9194 | AB25: =9318+1565 -> 10883 | AC25: 0 | AD25: 0 | AE25: 0 | AF25: 0
T26: projected | U26: =U24+(U24*$AI23/100) -> 757.475 | V26: =V24+(V24*$AI23/100) -> 6052.625 | W26: =W24+(W24*$AI23/100) -> 6433.6021 | X26: =X24+(X24*$AI23/100) -> 6433.6021 | Y26: =Y24+(Y24*$AI23/100) -> 7888.4 | Z26: =Z24+(Z24*$AI23/100) -> 8516.725 | AA26: =AA24+(AA24*$AI23/100) -> 8530.05 | AB26: =AB24+(AB24*$AI23/100) -> 10023.475 | ... AF26: =AF24+(AF24*$AI23/100) -> 14469.104
T27: growth | U27: 0 | V27: =V25/V24 - 1 -> 0.033022862 | W27: =W25/W24 - 1 -> 0.086082857 | X27: =X25/X24 - 1 -> 0.036046242 | Y27: =Y25/Y24 - 1 -> 0.065488565 | Z27: =Z25/Z24 - 1 -> 0 | AA27: =AA25/AA24 - 1 -> 0.1047825 | AB27: =AB25/AB24 - 1 -> 0.11289498
U28: 24/01 | V28: 24/02 | W28: 24/03 | X28: 24/04 | Y28: 24/05 | Z28: 24/06 | AA28: 24/07 | AB28: 24/08 | AC28: 24/09 | AD28: 24/10 | AE28: 24/11 | AF28: 24/12
G32: V
